Workbook

Sheet Dashboard
B2: PROCUREMENT INTELLIGENCE DASHBOARD │ Purchasing analysis 2024–2025
B4: ="Database: "&FIXED(Calculations!$B$3,0)&" transactions │ "&FIXED(Calculations!$B$2/1000000,1)&" M PLN spend │ "&Calculations!$B$4&" suppliers, "&Calculations!$B$5&" buyers │ Anonymised data │ Author: P. Liberacki" -> Database: 100,000 transactions │ 6,295.6 M PLN spend │ 50 suppliers, 10 buyers │ Anonymised data │ Author: P. Liberacki
B6: TOTAL SPEND | E6: CATEGORY CONCENTRATION | H6: HIGHEST Y/Y GROWTH | K6: PARETO 80% OF SPEND | N6: LARGEST SINGLE TXN
B7: =Calculations!$B$2/1000000 -> 6295.5898 | E7: =Calculations!$B$15 -> 0.63530776 | H7: =Calculations!$B$17 -> 0.06912591 | K7: =Calculations!$B$20&" / "&Calculations!$B$4 -> 40 / 50 | N7: =Calculations!$B$9/1000000 -> 38.213365
B8: ="2024–2025 │ "&FIXED(Calculations!$B$3,0)&" txn" -> 2024–2025 │ 100,000 txn | E8: =Calculations!$B$16&" │ limit "&FIXED(Parameters!$B$10*100,0)&"%" -> IT Hardware │ limit 50% | H8: =Calculations!$B$18&" │ PPI ~"&FIXED(Parameters!$B$2*100,1)&"%" -> Marketing Services │ PPI ~3.5% | K8: ="suppliers │ TOP 5 = "&FIXED(Calculations!$B$21*100,1)&"%" -> suppliers │ TOP 5 = 12.4% | N8: =Calculations!$B$12&" │ "&Calculations!$B$13 -> SUP-46 │ IT Hardware
B10: ANOMALY VALUE | E10: PRICE ANOMALIES | H10: QUANTITY ANOMALIES | K10: PRICE OUTLIERS (μ+2σ) | N10: SPLIT ORDERS
B11: =Calculations!$B$7/1000000 -> 192.40621 | E11: =Calculations!$E$13&" txn" -> 50 txn | H11: =Calculations!$E$14&" txn" -> 30 txn | K11: =Calculations!$B$26&" txn" -> 304 txn | N11: =FIXED(Calculations!$B$32,0)&" cases" -> 2,177 cases
B12: =FIXED(Calculations!$B$6,0)&" txn │ "&FIXED(Calculations!$B$8*100,2)&"% spend" -> 80 txn │ 3.06% spend | E12: =FIXED(SUM(Calculations!$G$2:$G$7),1)&" M PLN" -> 26.9 M PLN | H12: =FIXED(SUM(Calculations!$H$2:$H$7),1)&" M PLN" -> 165.5 M PLN | K12: =FIXED(Calculations!$B$27,2)&" M PLN to review" -> 63.89 M PLN to review | N12: =FIXED(Calculations!$B$33,1)&" M PLN" -> 284.9 M PLN
B14: 1 │ SPEND ANALYSIS | H14: 2 │ ANOMALY MONITORING / AUDIT | N14: 3 │ SUPPLIER EVALUATION
B15: Spend by category – share of wallet | H15: Anomalies flagged in the database (transaction type) | N15: TOP 15 suppliers – spend and anomalies
B16: Category | C16: M PLN | D16: Share | E16: Change y/y | F16: Δ M PLN | H16: Type | I16: Txn | J16: M PLN | K16: % spend | L16: Most frequent cat. | N16: Supplier | O16: M PLN | P16: Share | Q16: Txn | R16: Anomalies
B17: =INDEX(Data_Categories!$A$2:$A$7,MATCH(LARGE(Data_Categories!$D$2:$D$7,1),Data_Categories!$D$2:$D$7,0)) -> IT Hardware | C17: =INDEX(Data_Categories!$D$2:$D$7,MATCH(LARGE(Data_Categories!$D$2:$D$7,1),Data_Categories!$D$2:$D$7,0)) -> 3999.58 | D17: =INDEX(Data_Categories!$E$2:$E$7,MATCH(LARGE(Data_Categories!$D$2:$D$7,1),Data_Categories!$D$2:$D$7,0)) -> 0.63530776 | E17: =INDEX(Data_Categories!$F$2:$F$7,MATCH(LARGE(Data_Categories!$D$2:$D$7,1),Data_Categories!$D$2:$D$7,0)) -> -0.025240082 | F17: =INDEX(Data_Categories!$G$2:$G$7,MATCH(LARGE(Data_Categories!$D$2:$D$7,1),Data_Categories!$D$2:$D$7,0)) -> -51.12 | H17: Price anomaly | I17: =SUM(Calculations!$E$2:$E$7) -> 50 | J17: =SUM(Calculations!$G$2:$G$7) -> 26.918312 | K17: =J17*1000000/Calculations!$B$2 -> 0.004275741 | L17: =Calculations!$E$11 -> Logistics | N17: =INDEX(Data_Suppliers!$A$2:$A$51,MATCH(LARGE(Data_Suppliers!$B$2:$B$51,1),Data_Suppliers!$B$2:$B$51,0)) -> SUP-18 | O17: =LARGE(Data_Suppliers!$B$2:$B$51,1)/1000000 -> 179.75338 | P17: =INDEX(Data_Suppliers!$E$2:$E$51,MATCH(LARGE(Data_Suppliers!$B$2:$B$51,1),Data_Suppliers!$B$2:$B$51,0)) -> 0.028552269 | Q17: =INDEX(Data_Suppliers!$C$2:$C$51,MATCH(LARGE(Data_Suppliers!$B$2:$B$51,1),Data_Suppliers!$B$2:$B$51,0)) -> 2012 | R17: =INDEX(Data_Suppliers!$F$2:$F$51,MATCH(LARGE(Data_Suppliers!$B$2:$B$51,1),Data_Suppliers!$B$2:$B$51,0)) -> 0
B18: =INDEX(Data_Categories!$A$2:$A$7,MATCH(LARGE(Data_Categories!$D$2:$D$7,2),Data_Categories!$D$2:$D$7,0)) -> Marketing Services | C18: =INDEX(Data_Categories!$D$2:$D$7,MATCH(LARGE(Data_Categories!$D$2:$D$7,2),Data_Categories!$D$2:$D$7,0)) -> 1218.86 | D18: =INDEX(Data_Categories!$E$2:$E$7,MATCH(LARGE(Data_Categories!$D$2:$D$7,2),Data_Categories!$D$2:$D$7,0)) -> 0.19360813 | E18: =INDEX(Data_Categories!$F$2:$F$7,MATCH(LARGE(Data_Categories!$D$2:$D$7,2),Data_Categories!$D$2:$D$7,0)) -> 0.06912591 | F18: =INDEX(Data_Categories!$G$2:$G$7,MATCH(LARGE(Data_Categories!$D$2:$D$7,2),Data_Categories!$D$2:$D$7,0)) -> 40.72 | H18: Quantity anomaly | I18: =SUM(Calculations!$F$2:$F$7) -> 30 | J18: =SUM(Calculations!$H$2:$H$7) -> 165.48789 | K18: =J18*1000000/Calculations!$B$2 -> 0.026286321 | L18: =Calculations!$E$12 -> Raw Materials | N18: =INDEX(Data_Suppliers!$A$2:$A$51,MATCH(LARGE(Data_Suppliers!$B$2:$B$51,2),Data_Suppliers!$B$2:$B$51,0)) -> SUP-46 | O18: =LARGE(Data_Suppliers!$B$2:$B$51,2)/1000000 -> 159.93085 | P18: =INDEX(Data_Suppliers!$E$2:$E$51,MATCH(LARGE(Data_Suppliers!$B$2:$B$51,2),Data_Suppliers!$B$2:$B$51,0)) -> 0.025403633 | Q18: =INDEX(Data_Suppliers!$C$2:$C$51,MATCH(LARGE(Data_Suppliers!$B$2:$B$51,2),Data_Suppliers!$B$2:$B$51,0)) -> 1988 | R18: =INDEX(Data_Suppliers!$F$2:$F$51,MATCH(LARGE(Data_Suppliers!$B$2:$B$51,2),Data_Suppliers!$B$2:$B$51,0)) -> 2
B19: =INDEX(Data_Categories!$A$2:$A$7,MATCH(LARGE(Data_Categories!$D$2:$D$7,3),Data_Categories!$D$2:$D$7,0)) -> Media & Energy | C19: =INDEX(Data_Categories!$D$2:$D$7,MATCH(LARGE(Data_Categories!$D$2:$D$7,3),Data_Categories!$D$2:$D$7,0)) -> 631.89 | D19: =INDEX(Data_Categories!$E$2:$E$7,MATCH(LARGE(Data_Categories!$D$2:$D$7,3),Data_Categories!$D$2:$D$7,0)) -> 0.10037169 | E19: =INDEX(Data_Categories!$F$2:$F$7,MATCH(LARGE(Data_Categories!$D$2:$D$7,3),Data_Categories!$D$2:$D$7,0)) -> 0.0058089706 | F19: =INDEX(Data_Categories!$G$2:$G$7,MATCH(LARGE(Data_Categories!$D$2:$D$7,3),Data_Categories!$D$2:$D$7,0)) -> 1.83 | H19: Total | I19: =I17+I18 -> 80 | J19: =J17+J18 -> 192.40621 | K19: =K17+K18 -> 0.030562062 | N19: =INDEX(Data_Suppliers!$A$2:$A$51,MATCH(LARGE(Data_Suppliers!$B$2:$B$51,3),Data_Suppliers!$B$2:$B$51,0)) -> SUP-12 | O19: =LARGE(Data_Suppliers!$B$2:$B$51,3)/1000000 -> 148.03815 | P19: =INDEX(Data_Suppliers!$E$2:$E$51,MATCH(LARGE(Data_Suppliers!$B$2:$B$51,3),Data_Suppliers!$B$2:$B$51,0)) -> 0.023514581 | Q19: =INDEX(Data_Suppliers!$C$2:$C$51,MATCH(LARGE(Data_Suppliers!$B$2:$B$51,3),Data_Suppliers!$B$2:$B$51,0)) -> 1976 | R19: =INDEX(Data_Suppliers!$F$2:$F$51,MATCH(LARGE(Data_Suppliers!$B$2:$B$51,3),Data_Suppliers!$B$2:$B$51,0)) -> 6
B20: =INDEX(Data_Categories!$A$2:$A$7,MATCH(LARGE(Data_Categories!$D$2:$D$7,4),Data_Categories!$D$2:$D$7,0)) -> Logistics | C20: =INDEX(Data_Categories!$D$2:$D$7,MATCH(LARGE(Data_Categories!$D$2:$D$7,4),Data_Categories!$D$2:$D$7,0)) -> 240.39 | D20: =INDEX(Data_Categories!$E$2:$E$7,MATCH(LARGE(Data_Categories!$D$2:$D$7,4),Data_Categories!$D$2:$D$7,0)) -> 0.038184417 | E20: =INDEX(Data_Categories!$F$2:$F$7,MATCH(LARGE(Data_Categories!$D$2:$D$7,4),Data_Categories!$D$2:$D$7,0)) -> 0.036340534 | F20: =INDEX(Data_Categories!$G$2:$G$7,MATCH(LARGE(Data_Categories!$D$2:$D$7,4),Data_Categories!$D$2:$D$7,0)) -> 4.29 | N20: =INDEX(Data_Suppliers!$A$2:$A$51,MATCH(LARGE(Data_Suppliers!$B$2:$B$51,4),Data_Suppliers!$B$2:$B$51,0)) -> SUP-14 | O20: =LARGE(Data_Suppliers!$B$2:$B$51,4)/1000000 -> 147.78608 | P20: =INDEX(Data_Suppliers!$E$2:$E$51,MATCH(LARGE(Data_Suppliers!$B$2:$B$51,4),Data_Suppliers!$B$2:$B$51,0)) -> 0.02347454 | Q20: =INDEX(Data_Suppliers!$C$2:$C$51,MATCH(LARGE(Data_Suppliers!$B$2:$B$51,4),Data_Suppliers!$B$2:$B$51,0)) -> 2073 | R20: =INDEX(Data_Suppliers!$F$2:$F$51,MATCH(LARGE(Data_Suppliers!$B$2:$B$51,4),Data_Suppliers!$B$2:$B$51,0)) -> 3
B21: =INDEX(Data_Categories!$A$2:$A$7,MATCH(LARGE(Data_Categories!$D$2:$D$7,5),Data_Categories!$D$2:$D$7,0)) -> Raw Materials | C21: =INDEX(Data_Categories!$D$2:$D$7,MATCH(LARGE(Data_Categories!$D$2:$D$7,5),Data_Categories!$D$2:$D$7,0)) -> 164.89 | D21: =INDEX(Data_Categories!$E$2:$E$7,MATCH(LARGE(Data_Categories!$D$2:$D$7,5),Data_Categories!$D$2:$D$7,0)) -> 0.026191724 | E21: =INDEX(Data_Categories!$F$2:$F$7,MATCH(LARGE(Data_Categories!$D$2:$D$7,5),Data_Categories!$D$2:$D$7,0)) -> -0.0023019142 | F21: =INDEX(Data_Categories!$G$2:$G$7,MATCH(LARGE(Data_Categories!$D$2:$D$7,5),Data_Categories!$D$2:$D$7,0)) -> -0.19 | H21: Statistical outliers (price > μ+2σ in category) | N21: =INDEX(Data_Suppliers!$A$2:$A$51,MATCH(LARGE(Data_Suppliers!$B$2:$B$51,5),Data_Suppliers!$B$2:$B$51,0)) -> SUP-30 | O21: =LARGE(Data_Suppliers!$B$2:$B$51,5)/1000000 -> 143.31574 | P21: =INDEX(Data_Suppliers!$E$2:$E$51,MATCH(LARGE(Data_Suppliers!$B$2:$B$51,5),Data_Suppliers!$B$2:$B$51,0)) -> 0.022764466 | Q21: =INDEX(Data_Suppliers!$C$2:$C$51,MATCH(LARGE(Data_Suppliers!$B$2:$B$51,5),Data_Suppliers!$B$2:$B$51,0)) -> 2012 | R21: =INDEX(Data_Suppliers!$F$2:$F$51,MATCH(LARGE(Data_Suppliers!$B$2:$B$51,5),Data_Suppliers!$B$2:$B$51,0)) -> 3
B22: =INDEX(Data_Categories!$A$2:$A$7,MATCH(LARGE(Data_Categories!$D$2:$D$7,6),Data_Categories!$D$2:$D$7,0)) -> Office Supplies | C22: =INDEX(Data_Categories!$D$2:$D$7,MATCH(LARGE(Data_Categories!$D$2:$D$7,6),Data_Categories!$D$2:$D$7,0)) -> 39.89 | D22: =INDEX(Data_Categories!$E$2:$E$7,MATCH(LARGE(Data_Categories!$D$2:$D$7,6),Data_Categories!$D$2:$D$7,0)) -> 0.0063362719 | E22: =INDEX(Data_Categories!$F$2:$F$7,MATCH(LARGE(Data_Categories!$D$2:$D$7,6),Data_Categories!$D$2:$D$7,0)) -> -0.0045022511 | F22: =INDEX(Data_Categories!$G$2:$G$7,MATCH(LARGE(Data_Categories!$D$2:$D$7,6),Data_Categories!$D$2:$D$7,0)) -> -0.09 | H22: Category | I22: Outliers | J22: M PLN | K22: Threshold PLN/u. | L22: Risk | N22: =INDEX(Data_Suppliers!$A$2:$A$51,MATCH(LARGE(Data_Suppliers!$B$2:$B$51,6),Data_Suppliers!$B$2:$B$51,0)) -> SUP-27 | O22: =LARGE(Data_Suppliers!$B$2:$B$51,6)/1000000 -> 135.62602 | P22: =INDEX(Data_Suppliers!$E$2:$E$51,MATCH(LARGE(Data_Suppliers!$B$2:$B$51,6),Data_Suppliers!$B$2:$B$51,0)) -> 0.02154302 | Q22: =INDEX(Data_Suppliers!$C$2:$C$51,MATCH(LARGE(Data_Suppliers!$B$2:$B$51,6),Data_Suppliers!$B$2:$B$51,0)) -> 2019 | R22: =INDEX(Data_Suppliers!$F$2:$F$51,MATCH(LARGE(Data_Suppliers!$B$2:$B$51,6),Data_Suppliers!$B$2:$B$51,0)) -> 2
B23: Total | C23: =SUM(C17:C22) -> 6295.5 | D23: =SUM(D17:D22) -> 1 | E23: =SUM(Data_Categories!$C$2:$C$7)/SUM(Data_Categories!$B$2:$B$7)-1 -> -0.0014476053 | F23: =SUM(F17:F22) -> -4.56 | H23: =INDEX(Data_Outliers!$A$2:$A7,MATCH(LARGE(Data_Outliers!$C$2:$C7,1),Data_Outliers!$C$2:$C7,0)) -> IT Hardware | I23: =INDEX(Data_Outliers!$B$2:$B7,MATCH(LARGE(Data_Outliers!$C$2:$C7,1),Data_Outliers!$C$2:$C7,0)) -> 76 | J23: =INDEX(Data_Outliers!$C$2:$C7,MATCH(LARGE(Data_Outliers!$C$2:$C7,1),Data_Outliers!$C$2:$C7,0)) -> 40.47 | K23: =INDEX(Data_Outliers!$D$2:$D7,MATCH(LARGE(Data_Outliers!$C$2:$C7,1),Data_Outliers!$C$2:$C7,0)) -> 7213 | L23: =INDEX(Data_Outliers!$E$2:$E7,MATCH(LARGE(Data_Outliers!$C$2:$C7,1),Data_Outliers!$C$2:$C7,0)) -> HIGH | N23: =INDEX(Data_Suppliers!$A$2:$A$51,MATCH(LARGE(Data_Suppliers!$B$2:$B$51,7),Data_Suppliers!$B$2:$B$51,0)) -> SUP-47 | O23: =LARGE(Data_Suppliers!$B$2:$B$51,7)/1000000 -> 133.40018 | P23: =INDEX(Data_Suppliers!$E$2:$E$51,MATCH(LARGE(Data_Suppliers!$B$2:$B$51,7),Data_Suppliers!$B$2:$B$51,0)) -> 0.021189465 | Q23: =INDEX(Data_Suppliers!$C$2:$C$51,MATCH(LARGE(Data_Suppliers!$B$2:$B$51,7),Data_Suppliers!$B$2:$B$51,0)) -> 2084 | R23: =INDEX(Data_Suppliers!$F$2:$F$51,MATCH(LARGE(Data_Suppliers!$B$2:$B$51,7),Data_Suppliers!$B$2:$B$51,0)) -> 2
H24: =INDEX(Data_Outliers!$A$2:$A7,MATCH(LARGE(Data_Outliers!$C$2:$C7,2),Data_Outliers!$C$2:$C7,0)) -> Marketing Services | I24: =INDEX(Data_Outliers!$B$2:$B7,MATCH(LARGE(Data_Outliers!$C$2:$C7,2),Data_Outliers!$C$2:$C7,0)) -> 27 | J24: =INDEX(Data_Outliers!$C$2:$C7,MATCH(LARGE(Data_Outliers!$C$2:$C7,2),Data_Outliers!$C$2:$C7,0)) -> 9.68 | K24: =INDEX(Data_Outliers!$D$2:$D7,MATCH(LARGE(Data_Outliers!$C$2:$C7,2),Data_Outliers!$C$2:$C7,0)) -> 2262 | L24: =INDEX(Data_Outliers!$E$2:$E7,MATCH(LARGE(Data_Outliers!$C$2:$C7,2),Data_Outliers!$C$2:$C7,0)) -> MEDIUM | N24: =INDEX(Data_Suppliers!$A$2:$A$51,MATCH(LARGE(Data_Suppliers!$B$2:$B$51,8),Data_Suppliers!$B$2:$B$51,0)) -> SUP-44 | O24: =LARGE(Data_Suppliers!$B$2:$B$51,8)/1000000 -> 131.41237 | P24: =INDEX(Data_Suppliers!$E$2:$E$51,MATCH(LARGE(Data_Suppliers!$B$2:$B$51,8),Data_Suppliers!$B$2:$B$51,0)) -> 0.020873718 | Q24: =INDEX(Data_Suppliers!$C$2:$C$51,MATCH(LARGE(Data_Suppliers!$B$2:$B$51,8),Data_Suppliers!$B$2:$B$51,0)) -> 2016 | R24: =INDEX(Data_Suppliers!$F$2:$F$51,MATCH(LARGE(Data_Suppliers!$B$2:$B$51,8),Data_Suppliers!$B$2:$B$51,0)) -> 2
B25: Monthly trend 2024 vs 2025 (M PLN) | H25: =INDEX(Data_Outliers!$A$2:$A7,MATCH(LARGE(Data_Outliers!$C$2:$C7,3),Data_Outliers!$C$2:$C7,0)) -> Media & Energy | I25: =INDEX(Data_Outliers!$B$2:$B7,MATCH(LARGE(Data_Outliers!$C$2:$C7,3),Data_Outliers!$C$2:$C7,0)) -> 166 | J25: =INDEX(Data_Outliers!$C$2:$C7,MATCH(LARGE(Data_Outliers!$C$2:$C7,3),Data_Outliers!$C$2:$C7,0)) -> 9.5 | K25: =INDEX(Data_Outliers!$D$2:$D7,MATCH(LARGE(Data_Outliers!$C$2:$C7,3),Data_Outliers!$C$2:$C7,0)) -> 1031 | L25: =INDEX(Data_Outliers!$E$2:$E7,MATCH(LARGE(Data_Outliers!$C$2:$C7,3),Data_Outliers!$C$2:$C7,0)) -> MEDIUM | N25: =INDEX(Data_Suppliers!$A$2:$A$51,MATCH(LARGE(Data_Suppliers!$B$2:$B$51,9),Data_Suppliers!$B$2:$B$51,0)) -> SUP-05 | O25: =LARGE(Data_Suppliers!$B$2:$B$51,9)/1000000 -> 131.26485 | P25: =INDEX(Data_Suppliers!$E$2:$E$51,MATCH(LARGE(Data_Suppliers!$B$2:$B$51,9),Data_Suppliers!$B$2:$B$51,0)) -> 0.020850286 | Q25: =INDEX(Data_Suppliers!$C$2:$C$51,MATCH(LARGE(Data_Suppliers!$B$2:$B$51,9),Data_Suppliers!$B$2:$B$51,0)) -> 2053 | R25: =INDEX(Data_Suppliers!$F$2:$F$51,MATCH(LARGE(Data_Suppliers!$B$2:$B$51,9),Data_Suppliers!$B$2:$B$51,0)) -> 0
B26: Month | C26: 2024 | D26: 2025 | E26: Δ M PLN | F26: Δ % | H26: =INDEX(Data_Outliers!$A$2:$A7,MATCH(LARGE(Data_Outliers!$C$2:$C7,4),Data_Outliers!$C$2:$C7,0)) -> Logistics | I26: =INDEX(Data_Outliers!$B$2:$B7,MATCH(LARGE(Data_Outliers!$C$2:$C7,4),Data_Outliers!$C$2:$C7,0)) -> 13 | J26: =INDEX(Data_Outliers!$C$2:$C7,MATCH(LARGE(Data_Outliers!$C$2:$C7,4),Data_Outliers!$C$2:$C7,0)) -> 3.02 | K26: =INDEX(Data_Outliers!$D$2:$D7,MATCH(LARGE(Data_Outliers!$C$2:$C7,4),Data_Outliers!$C$2:$C7,0)) -> 510 | L26: =INDEX(Data_Outliers!$E$2:$E7,MATCH(LARGE(Data_Outliers!$C$2:$C7,4),Data_Outliers!$C$2:$C7,0)) -> LOW | N26: =INDEX(Data_Suppliers!$A$2:$A$51,MATCH(LARGE(Data_Suppliers!$B$2:$B$51,10),Data_Suppliers!$B$2:$B$51,0)) -> SUP-39 | O26: =LARGE(Data_Suppliers!$B$2:$B$51,10)/1000000 -> 130.93816 | P26: =INDEX(Data_Suppliers!$E$2:$E$51,MATCH(LARGE(Data_Suppliers!$B$2:$B$51,10),Data_Suppliers!$B$2:$B$51,0)) -> 0.020798394 | Q26: =INDEX(Data_Suppliers!$C$2:$C$51,MATCH(LARGE(Data_Suppliers!$B$2:$B$51,10),Data_Suppliers!$B$2:$B$51,0)) -> 2014 | R26: =INDEX(Data_Suppliers!$F$2:$F$51,MATCH(LARGE(Data_Suppliers!$B$2:$B$51,10),Data_Suppliers!$B$2:$B$51,0)) -> 2
B27: =Data_Months!A2 -> Jan | C27: =Data_Months!B2 -> 256.8 | D27: =Data_Months!C2 -> 261.1 | E27: =Data_Months!D2 -> 4.3 | F27: =Data_Months!E2 -> 0.016744548 | H27: =INDEX(Data_Outliers!$A$2:$A7,MATCH(LARGE(Data_Outliers!$C$2:$C7,5),Data_Outliers!$C$2:$C7,0)) -> Raw Materials | I27: =INDEX(Data_Outliers!$B$2:$B7,MATCH(LARGE(Data_Outliers!$C$2:$C7,5),Data_Outliers!$C$2:$C7,0)) -> 10 | J27: =INDEX(Data_Outliers!$C$2:$C7,MATCH(LARGE(Data_Outliers!$C$2:$C7,5),Data_Outliers!$C$2:$C7,0)) -> 0.83 | K27: =INDEX(Data_Outliers!$D$2:$D7,MATCH(LARGE(Data_Outliers!$C$2:$C7,5),Data_Outliers!$C$2:$C7,0)) -> 320 | L27: =INDEX(Data_Outliers!$E$2:$E7,MATCH(LARGE(Data_Outliers!$C$2:$C7,5),Data_Outliers!$C$2:$C7,0)) -> LOW | N27: =INDEX(Data_Suppliers!$A$2:$A$51,MATCH(LARGE(Data_Suppliers!$B$2:$B$51,11),Data_Suppliers!$B$2:$B$51,0)) -> SUP-04 | O27: =LARGE(Data_Suppliers!$B$2:$B$51,11)/1000000 -> 129.96584 | P27: =INDEX(Data_Suppliers!$E$2:$E$51,MATCH(LARGE(Data_Suppliers!$B$2:$B$51,11),Data_Suppliers!$B$2:$B$51,0)) -> 0.02064395 | Q27: =INDEX(Data_Suppliers!$C$2:$C$51,MATCH(LARGE(Data_Suppliers!$B$2:$B$51,11),Data_Suppliers!$B$2:$B$51,0)) -> 2078 | R27: =INDEX(Data_Suppliers!$F$2:$F$51,MATCH(LARGE(Data_Suppliers!$B$2:$B$51,11),Data_Suppliers!$B$2:$B$51,0)) -> 0
B28: =Data_Months!A3 -> Feb | C28: =Data_Months!B3 -> 239.6 | D28: =Data_Months!C3 -> 236.1 | E28: =Data_Months!D3 -> -3.5 | F28: =Data_Months!E3 -> -0.014607679 | H28: =INDEX(Data_Outliers!$A$2:$A7,MATCH(LARGE(Data_Outliers!$C$2:$C7,6),Data_Outliers!$C$2:$C7,0)) -> Office Supplies | I28: =INDEX(Data_Outliers!$B$2:$B7,MATCH(LARGE(Data_Outliers!$C$2:$C7,6),Data_Outliers!$C$2:$C7,0)) -> 12 | J28: =INDEX(Data_Outliers!$C$2:$C7,MATCH(LARGE(Data_Outliers!$C$2:$C7,6),Data_Outliers!$C$2:$C7,0)) -> 0.39 | K28: =INDEX(Data_Outliers!$D$2:$D7,MATCH(LARGE(Data_Outliers!$C$2:$C7,6),Data_Outliers!$C$2:$C7,0)) -> 82 | L28: =INDEX(Data_Outliers!$E$2:$E7,MATCH(LARGE(Data_Outliers!$C$2:$C7,6),Data_Outliers!$C$2:$C7,0)) -> LOW | N28: =INDEX(Data_Suppliers!$A$2:$A$51,MATCH(LARGE(Data_Suppliers!$B$2:$B$51,12),Data_Suppliers!$B$2:$B$51,0)) -> SUP-01 | O28: =LARGE(Data_Suppliers!$B$2:$B$51,12)/1000000 -> 129.04028 | P28: =INDEX(Data_Suppliers!$E$2:$E$51,MATCH(LARGE(Data_Suppliers!$B$2:$B$51,12),Data_Suppliers!$B$2:$B$51,0)) -> 0.020496932 | Q28: =INDEX(Data_Suppliers!$C$2:$C$51,MATCH(LARGE(Data_Suppliers!$B$2:$B$51,12),Data_Suppliers!$B$2:$B$51,0)) -> 2018 | R28: =INDEX(Data_Suppliers!$F$2:$F$51,MATCH(LARGE(Data_Suppliers!$B$2:$B$51,12),Data_Suppliers!$B$2:$B$51,0)) -> 5
B29: =Data_Months!A4 -> Mar | C29: =Data_Months!B4 -> 262.4 | D29: =Data_Months!C4 -> 282 | E29: =Data_Months!D4 -> 19.6 | F29: =Data_Months!E4 -> 0.074695122 | H29: Total | I29: =SUM(I23:I28) -> 304 | J29: =SUM(J23:J28) -> 63.89 | N29: =INDEX(Data_Suppliers!$A$2:$A$51,MATCH(LARGE(Data_Suppliers!$B$2:$B$51,13),Data_Suppliers!$B$2:$B$51,0)) -> SUP-33 | O29: =LARGE(Data_Suppliers!$B$2:$B$51,13)/1000000 -> 128.6783 | P29: =INDEX(Data_Suppliers!$E$2:$E$51,MATCH(LARGE(Data_Suppliers!$B$2:$B$51,13),Data_Suppliers!$B$2:$B$51,0)) -> 0.020439435 | Q29: =INDEX(Data_Suppliers!$C$2:$C$51,MATCH(LARGE(Data_Suppliers!$B$2:$B$51,13),Data_Suppliers!$B$2:$B$51,0)) -> 2028 | R29: =INDEX(Data_Suppliers!$F$2:$F$51,MATCH(LARGE(Data_Suppliers!$B$2:$B$51,13),Data_Suppliers!$B$2:$B$51,0)) -> 1
B30: =Data_Months!A5 -> Apr | C30: =Data_Months!B5 -> 244.1 | D30: =Data_Months!C5 -> 255.5 | E30: =Data_Months!D5 -> 11.4 | F30: =Data_Months!E5 -> 0.046702171 | N30: =INDEX(Data_Suppliers!$A$2:$A$51,MATCH(LARGE(Data_Suppliers!$B$2:$B$51,14),Data_Suppliers!$B$2:$B$51,0)) -> SUP-08 | O30: =LARGE(Data_Suppliers!$B$2:$B$51,14)/1000000 -> 128.49488 | P30: =INDEX(Data_Suppliers!$E$2:$E$51,MATCH(LARGE(Data_Suppliers!$B$2:$B$51,14),Data_Suppliers!$B$2:$B$51,0)) -> 0.020410301 | Q30: =INDEX(Data_Suppliers!$C$2:$C$51,MATCH(LARGE(Data_Suppliers!$B$2:$B$51,14),Data_Suppliers!$B$2:$B$51,0)) -> 2027 | R30: =INDEX(Data_Suppliers!$F$2:$F$51,MATCH(LARGE(Data_Suppliers!$B$2:$B$51,14),Data_Suppliers!$B$2:$B$51,0)) -> 2
B31: =Data_Months!A6 -> May | C31: =Data_Months!B6 -> 260 | D31: =Data_Months!C6 -> 271.3 | E31: =Data_Months!D6 -> 11.3 | F31: =Data_Months!E6 -> 0.043461538 | H31: TOP 5 anomalous transactions (by value) | N31: =INDEX(Data_Suppliers!$A$2:$A$51,MATCH(LARGE(Data_Suppliers!$B$2:$B$51,15),Data_Suppliers!$B$2:$B$51,0)) -> SUP-43 | O31: =LARGE(Data_Suppliers!$B$2:$B$51,15)/1000000 -> 127.94361 | P31: =INDEX(Data_Suppliers!$E$2:$E$51,MATCH(LARGE(Data_Suppliers!$B$2:$B$51,15),Data_Suppliers!$B$2:$B$51,0)) -> 0.020322736 | Q31: =INDEX(Data_Suppliers!$C$2:$C$51,MATCH(LARGE(Data_Suppliers!$B$2:$B$51,15),Data_Suppliers!$B$2:$B$51,0)) -> 1922 | R31: =INDEX(Data_Suppliers!$F$2:$F$51,MATCH(LARGE(Data_Suppliers!$B$2:$B$51,15),Data_Suppliers!$B$2:$B$51,0)) -> 3
B32: =Data_Months!A7 -> Jun | C32: =Data_Months!B7 -> 255.6 | D32: =Data_Months!C7 -> 254.9 | E32: =Data_Months!D7 -> -0.7 | F32: =Data_Months!E7 -> -0.0027386541 | H32: Order ID | I32: Date | J32: Supplier | K32: M PLN | L32: Type
B33: =Data_Months!A8 -> Jul | C33: =Data_Months!B8 -> 260.4 | D33: =Data_Months!C8 -> 262.8 | E33: =Data_Months!D8 -> 2.4 | F33: =Data_Months!E8 -> 0.0092165899 | H33: =INDEX(Data_Anomalies!$A$2:$A$81,MATCH(LARGE(Data_Anomalies!$I$2:$I$81,1),Data_Anomalies!$I$2:$I$81,0)) -> PO-817370 | I33: =INDEX(Data_Anomalies!$B$2:$B$81,MATCH(LARGE(Data_Anomalies!$I$2:$I$81,1),Data_Anomalies!$I$2:$I$81,0)) -> 45535 | J33: =INDEX(Data_Anomalies!$D$2:$D$81,MATCH(LARGE(Data_Anomalies!$I$2:$I$81,1),Data_Anomalies!$I$2:$I$81,0)) -> SUP-46 | K33: =LARGE(Data_Anomalies!$I$2:$I$81,1)/1000000 -> 38.213365 | L33: =INDEX(Data_Anomalies!$H$2:$H$81,MATCH(LARGE(Data_Anomalies!$I$2:$I$81,1),Data_Anomalies!$I$2:$I$81,0)) -> Quantity anomaly | N33: Risk scorecard – TOP 8 by anomaly value
B34: =Data_Months!A9 -> Aug | C34: =Data_Months!B9 -> 290.8 | D34: =Data_Months!C9 -> 272.5 | E34: =Data_Months!D9 -> -18.3 | F34: =Data_Months!E9 -> -0.062929849 | H34: =INDEX(Data_Anomalies!$A$2:$A$81,MATCH(LARGE(Data_Anomalies!$I$2:$I$81,2),Data_Anomalies!$I$2:$I$81,0)) -> PO-663941 | I34: =INDEX(Data_Anomalies!$B$2:$B$81,MATCH(LARGE(Data_Anomalies!$I$2:$I$81,2),Data_Anomalies!$I$2:$I$81,0)) -> 45509 | J34: =INDEX(Data_Anomalies!$D$2:$D$81,MATCH(LARGE(Data_Anomalies!$I$2:$I$81,2),Data_Anomalies!$I$2:$I$81,0)) -> SUP-14 | K34: =LARGE(Data_Anomalies!$I$2:$I$81,2)/1000000 -> 22.13805 | L34: =INDEX(Data_Anomalies!$H$2:$H$81,MATCH(LARGE(Data_Anomalies!$I$2:$I$81,2),Data_Anomalies!$I$2:$I$81,0)) -> Quantity anomaly | N34: Supplier | O34: # anom. | P34: M PLN | Q34: Top category | R34: Rating
B35: =Data_Months!A10 -> Sep | C35: =Data_Months!B10 -> 302.9 | D35: =Data_Months!C10 -> 261.1 | E35: =Data_Months!D10 -> -41.8 | F35: =Data_Months!E10 -> -0.13799934 | H35: =INDEX(Data_Anomalies!$A$2:$A$81,MATCH(LARGE(Data_Anomalies!$I$2:$I$81,3),Data_Anomalies!$I$2:$I$81,0)) -> PO-417578 | I35: =INDEX(Data_Anomalies!$B$2:$B$81,MATCH(LARGE(Data_Anomalies!$I$2:$I$81,3),Data_Anomalies!$I$2:$I$81,0)) -> 45738 | J35: =INDEX(Data_Anomalies!$D$2:$D$81,MATCH(LARGE(Data_Anomalies!$I$2:$I$81,3),Data_Anomalies!$I$2:$I$81,0)) -> SUP-30 | K35: =LARGE(Data_Anomalies!$I$2:$I$81,3)/1000000 -> 17.329718 | L35: =INDEX(Data_Anomalies!$H$2:$H$81,MATCH(LARGE(Data_Anomalies!$I$2:$I$81,3),Data_Anomalies!$I$2:$I$81,0)) -> Quantity anomaly | N35: =INDEX(Data_Suppliers!$A$2:$A$51,MATCH(LARGE(Data_Suppliers!$G$2:$G$51,1),Data_Suppliers!$G$2:$G$51,0)) -> SUP-46 | O35: =INDEX(Data_Suppliers!$F$2:$F$51,MATCH(LARGE(Data_Suppliers!$G$2:$G$51,1),Data_Suppliers!$G$2:$G$51,0)) -> 2 | P35: =LARGE(Data_Suppliers!$G$2:$G$51,1)/1000000 -> 38.217839 | Q35: =INDEX(Data_Suppliers!$P$2:$P$51,MATCH(LARGE(Data_Suppliers!$G$2:$G$51,1),Data_Suppliers!$G$2:$G$51,0)) -> IT Hardware | R35: =INDEX(Data_Suppliers!$H$2:$H$51,MATCH(LARGE(Data_Suppliers!$G$2:$G$51,1),Data_Suppliers!$G$2:$G$51,0)) -> ELEVATED
B36: =Data_Months!A11 -> Oct | C36: =Data_Months!B11 -> 264.2 | D36: =Data_Months!C11 -> 270.2 | E36: =Data_Months!D11 -> 6 | F36: =Data_Months!E11 -> 0.022710068 | H36: =INDEX(Data_Anomalies!$A$2:$A$81,MATCH(LARGE(Data_Anomalies!$I$2:$I$81,4),Data_Anomalies!$I$2:$I$81,0)) -> PO-393878 | I36: =INDEX(Data_Anomalies!$B$2:$B$81,MATCH(LARGE(Data_Anomalies!$I$2:$I$81,4),Data_Anomalies!$I$2:$I$81,0)) -> 45993 | J36: =INDEX(Data_Anomalies!$D$2:$D$81,MATCH(LARGE(Data_Anomalies!$I$2:$I$81,4),Data_Anomalies!$I$2:$I$81,0)) -> SUP-12 | K36: =LARGE(Data_Anomalies!$I$2:$I$81,4)/1000000 -> 13.78269 | L36: =INDEX(Data_Anomalies!$H$2:$H$81,MATCH(LARGE(Data_Anomalies!$I$2:$I$81,4),Data_Anomalies!$I$2:$I$81,0)) -> Quantity anomaly | N36: =INDEX(Data_Suppliers!$A$2:$A$51,MATCH(LARGE(Data_Suppliers!$G$2:$G$51,2),Data_Suppliers!$G$2:$G$51,0)) -> SUP-12 | O36: =INDEX(Data_Suppliers!$F$2:$F$51,MATCH(LARGE(Data_Suppliers!$G$2:$G$51,2),Data_Suppliers!$G$2:$G$51,0)) -> 6 | P36: =LARGE(Data_Suppliers!$G$2:$G$51,2)/1000000 -> 29.146079 | Q36: =INDEX(Data_Suppliers!$P$2:$P$51,MATCH(LARGE(Data_Suppliers!$G$2:$G$51,2),Data_Suppliers!$G$2:$G$51,0)) -> IT Hardware | R36: =INDEX(Data_Suppliers!$H$2:$H$51,MATCH(LARGE(Data_Suppliers!$G$2:$G$51,2),Data_Suppliers!$G$2:$G$51,0)) -> HIGH
B37: =Data_Months!A12 -> Nov | C37: =Data_Months!B12 -> 255.9 | D37: =Data_Months!C12 -> 261.9 | E37: =Data_Months!D12 -> 6 | F37: =Data_Months!E12 -> 0.023446659 | H37: =INDEX(Data_Anomalies!$A$2:$A$81,MATCH(LARGE(Data_Anomalies!$I$2:$I$81,5),Data_Anomalies!$I$2:$I$81,0)) -> PO-474907 | I37: =INDEX(Data_Anomalies!$B$2:$B$81,MATCH(LARGE(Data_Anomalies!$I$2:$I$81,5),Data_Anomalies!$I$2:$I$81,0)) -> 45874 | J37: =INDEX(Data_Anomalies!$D$2:$D$81,MATCH(LARGE(Data_Anomalies!$I$2:$I$81,5),Data_Anomalies!$I$2:$I$81,0)) -> SUP-12 | K37: =LARGE(Data_Anomalies!$I$2:$I$81,5)/1000000 -> 10.47301 | L37: =INDEX(Data_Anomalies!$H$2:$H$81,MATCH(LARGE(Data_Anomalies!$I$2:$I$81,5),Data_Anomalies!$I$2:$I$81,0)) -> Quantity anomaly | N37: =INDEX(Data_Suppliers!$A$2:$A$51,MATCH(LARGE(Data_Suppliers!$G$2:$G$51,3),Data_Suppliers!$G$2:$G$51,0)) -> SUP-14 | O37: =INDEX(Data_Suppliers!$F$2:$F$51,MATCH(LARGE(Data_Suppliers!$G$2:$G$51,3),Data_Suppliers!$G$2:$G$51,0)) -> 3 | P37: =LARGE(Data_Suppliers!$G$2:$G$51,3)/1000000 -> 27.10715 | Q37: =INDEX(Data_Suppliers!$P$2:$P$51,MATCH(LARGE(Data_Suppliers!$G$2:$G$51,3),Data_Suppliers!$G$2:$G$51,0)) -> IT Hardware | R37: =INDEX(Data_Suppliers!$H$2:$H$51,MATCH(LARGE(Data_Suppliers!$G$2:$G$51,3),Data_Suppliers!$G$2:$G$51,0)) -> ELEVATED
B38: =Data_Months!A13 -> Dec | C38: =Data_Months!B13 -> 257.2 | D38: =Data_Months!C13 -> 255.9 | E38: =Data_Months!D13 -> -1.3 | F38: =Data_Months!E13 -> -0.0050544323 | N38: =INDEX(Data_Suppliers!$A$2:$A$51,MATCH(LARGE(Data_Suppliers!$G$2:$G$51,4),Data_Suppliers!$G$2:$G$51,0)) -> SUP-30 | O38: =INDEX(Data_Suppliers!$F$2:$F$51,MATCH(LARGE(Data_Suppliers!$G$2:$G$51,4),Data_Suppliers!$G$2:$G$51,0)) -> 3 | P38: =LARGE(Data_Suppliers!$G$2:$G$51,4)/1000000 -> 19.467356 | Q38: =INDEX(Data_Suppliers!$P$2:$P$51,MATCH(LARGE(Data_Suppliers!$G$2:$G$51,4),Data_Suppliers!$G$2:$G$51,0)) -> IT Hardware | R38: =INDEX(Data_Suppliers!$H$2:$H$51,MATCH(LARGE(Data_Suppliers!$G$2:$G$51,4),Data_Suppliers!$G$2:$G$51,0)) -> ELEVATED
B39: Total | C39: =SUM(C27:C38) -> 3149.9 | D39: =SUM(D27:D38) -> 3145.3 | E39: =D39-C39 -> -4.6 | F39: =D39/C39-1 -> -0.0014603638 | H39: Buyers – value of anomalous transactions | N39: =INDEX(Data_Suppliers!$A$2:$A$51,MATCH(LARGE(Data_Suppliers!$G$2:$G$51,5),Data_Suppliers!$G$2:$G$51,0)) -> SUP-33 | O39: =INDEX(Data_Suppliers!$F$2:$F$51,MATCH(LARGE(Data_Suppliers!$G$2:$G$51,5),Data_Suppliers!$G$2:$G$51,0)) -> 1 | P39: =LARGE(Data_Suppliers!$G$2:$G$51,5)/1000000 -> 10.014222 | Q39: =INDEX(Data_Suppliers!$P$2:$P$51,MATCH(LARGE(Data_Suppliers!$G$2:$G$51,5),Data_Suppliers!$G$2:$G$51,0)) -> Marketing Services | R39: =INDEX(Data_Suppliers!$H$2:$H$51,MATCH(LARGE(Data_Suppliers!$G$2:$G$51,5),Data_Suppliers!$G$2:$G$51,0)) -> LOW
H40: Buyer | I40: # anom. | J40: M PLN | K40: % anom. value | L40: Level | N40: =INDEX(Data_Suppliers!$A$2:$A$51,MATCH(LARGE(Data_Suppliers!$G$2:$G$51,6),Data_Suppliers!$G$2:$G$51,0)) -> SUP-01 | O40: =INDEX(Data_Suppliers!$F$2:$F$51,MATCH(LARGE(Data_Suppliers!$G$2:$G$51,6),Data_Suppliers!$G$2:$G$51,0)) -> 5 | P40: =LARGE(Data_Suppliers!$G$2:$G$51,6)/1000000 -> 8.2091568 | Q40: =INDEX(Data_Suppliers!$P$2:$P$51,MATCH(LARGE(Data_Suppliers!$G$2:$G$51,6),Data_Suppliers!$G$2:$G$51,0)) -> Marketing Services | R40: =INDEX(Data_Suppliers!$H$2:$H$51,MATCH(LARGE(Data_Suppliers!$G$2:$G$51,6),Data_Suppliers!$G$2:$G$51,0)) -> HIGH
B41: Monthly trend – chart (M PLN) | H41: =INDEX(Data_Buyers!$A$2:$A$11,MATCH(LARGE(Data_Buyers!$F$2:$F$11,1),Data_Buyers!$F$2:$F$11,0)) -> BUYER-06 | I41: =INDEX(Data_Buyers!$E$2:$E$11,MATCH(LARGE(Data_Buyers!$F$2:$F$11,1),Data_Buyers!$F$2:$F$11,0)) -> 8 | J41: =LARGE(Data_Buyers!$F$2:$F$11,1)/1000000 -> 47.409539 | K41: =INDEX(Data_Buyers!$G$2:$G$11,MATCH(LARGE(Data_Buyers!$F$2:$F$11,1),Data_Buyers!$F$2:$F$11,0)) -> 0.24640338 | L41: =INDEX(Data_Buyers!$H$2:$H$11,MATCH(LARGE(Data_Buyers!$F$2:$F$11,1),Data_Buyers!$F$2:$F$11,0)) -> HIGH | N41: =INDEX(Data_Suppliers!$A$2:$A$51,MATCH(LARGE(Data_Suppliers!$G$2:$G$51,7),Data_Suppliers!$G$2:$G$51,0)) -> SUP-22 | O41: =INDEX(Data_Suppliers!$F$2:$F$51,MATCH(LARGE(Data_Suppliers!$G$2:$G$51,7),Data_Suppliers!$G$2:$G$51,0)) -> 1 | P41: =LARGE(Data_Suppliers!$G$2:$G$51,7)/1000000 -> 8.012495 | Q41: =INDEX(Data_Suppliers!$P$2:$P$51,MATCH(LARGE(Data_Suppliers!$G$2:$G$51,7),Data_Suppliers!$G$2:$G$51,0)) -> Marketing Services | R41: =INDEX(Data_Suppliers!$H$2:$H$51,MATCH(LARGE(Data_Suppliers!$G$2:$G$51,7),Data_Suppliers!$G$2:$G$51,0)) -> LOW
H42: =INDEX(Data_Buyers!$A$2:$A$11,MATCH(LARGE(Data_Buyers!$F$2:$F$11,2),Data_Buyers!$F$2:$F$11,0)) -> BUYER-02 | I42: =INDEX(Data_Buyers!$E$2:$E$11,MATCH(LARGE(Data_Buyers!$F$2:$F$11,2),Data_Buyers!$F$2:$F$11,0)) -> 8 | J42: =LARGE(Data_Buyers!$F$2:$F$11,2)/1000000 -> 38.967941 | K42: =INDEX(Data_Buyers!$G$2:$G$11,MATCH(LARGE(Data_Buyers!$F$2:$F$11,2),Data_Buyers!$F$2:$F$11,0)) -> 0.20252955 | L42: =INDEX(Data_Buyers!$H$2:$H$11,MATCH(LARGE(Data_Buyers!$F$2:$F$11,2),Data_Buyers!$F$2:$F$11,0)) -> HIGH | N42: =INDEX(Data_Suppliers!$A$2:$A$51,MATCH(LARGE(Data_Suppliers!$G$2:$G$51,8),Data_Suppliers!$G$2:$G$51,0)) -> SUP-43 | O42: =INDEX(Data_Suppliers!$F$2:$F$51,MATCH(LARGE(Data_Suppliers!$G$2:$G$51,8),Data_Suppliers!$G$2:$G$51,0)) -> 3 | P42: =LARGE(Data_Suppliers!$G$2:$G$51,8)/1000000 -> 7.2158463 | Q42: =INDEX(Data_Suppliers!$P$2:$P$51,MATCH(LARGE(Data_Suppliers!$G$2:$G$51,8),Data_Suppliers!$G$2:$G$51,0)) -> Marketing Services | R42: =INDEX(Data_Suppliers!$H$2:$H$51,MATCH(LARGE(Data_Suppliers!$G$2:$G$51,8),Data_Suppliers!$G$2:$G$51,0)) -> ELEVATED
H43: =INDEX(Data_Buyers!$A$2:$A$11,MATCH(LARGE(Data_Buyers!$F$2:$F$11,3),Data_Buyers!$F$2:$F$11,0)) -> BUYER-09 | I43: =INDEX(Data_Buyers!$E$2:$E$11,MATCH(LARGE(Data_Buyers!$F$2:$F$11,3),Data_Buyers!$F$2:$F$11,0)) -> 10 | J43: =LARGE(Data_Buyers!$F$2:$F$11,3)/1000000 -> 37.437345 | K43: =INDEX(Data_Buyers!$G$2:$G$11,MATCH(LARGE(Data_Buyers!$F$2:$F$11,3),Data_Buyers!$F$2:$F$11,0)) -> 0.19457452 | L43: =INDEX(Data_Buyers!$H$2:$H$11,MATCH(LARGE(Data_Buyers!$F$2:$F$11,3),Data_Buyers!$F$2:$F$11,0)) -> HIGH
H44: =INDEX(Data_Buyers!$A$2:$A$11,MATCH(LARGE(Data_Buyers!$F$2:$F$11,4),Data_Buyers!$F$2:$F$11,0)) -> BUYER-05 | I44: =INDEX(Data_Buyers!$E$2:$E$11,MATCH(LARGE(Data_Buyers!$F$2:$F$11,4),Data_Buyers!$F$2:$F$11,0)) -> 7 | J44: =LARGE(Data_Buyers!$F$2:$F$11,4)/1000000 -> 18.629954 | K44: =INDEX(Data_Buyers!$G$2:$G$11,MATCH(LARGE(Data_Buyers!$F$2:$F$11,4),Data_Buyers!$F$2:$F$11,0)) -> 0.096826161 | L44: =INDEX(Data_Buyers!$H$2:$H$11,MATCH(LARGE(Data_Buyers!$F$2:$F$11,4),Data_Buyers!$F$2:$F$11,0)) -> MEDIUM | N44: Buyers – spend and activity
H45: =INDEX(Data_Buyers!$A$2:$A$11,MATCH(LARGE(Data_Buyers!$F$2:$F$11,5),Data_Buyers!$F$2:$F$11,0)) -> BUYER-08 | I45: =INDEX(Data_Buyers!$E$2:$E$11,MATCH(LARGE(Data_Buyers!$F$2:$F$11,5),Data_Buyers!$F$2:$F$11,0)) -> 10 | J45: =LARGE(Data_Buyers!$F$2:$F$11,5)/1000000 -> 16.359617 | K45: =INDEX(Data_Buyers!$G$2:$G$11,MATCH(LARGE(Data_Buyers!$F$2:$F$11,5),Data_Buyers!$F$2:$F$11,0)) -> 0.08502645 | L45: =INDEX(Data_Buyers!$H$2:$H$11,MATCH(LARGE(Data_Buyers!$F$2:$F$11,5),Data_Buyers!$F$2:$F$11,0)) -> HIGH | N45: Buyer | O45: M PLN | P45: Txn | Q45: Avg txn PLN | R45: Anomalies
...

Sheet Methodology
A1: PROCUREMENT INTELLIGENCE DASHBOARD – methodology
A2: Goal | B2: A quick review of 2 years of purchasing: where the money goes, which transactions look suspicious, which suppliers and buyers need attention, and what to do first.
A3: Data source | B3: A database of 100,000 purchase transactions (2024–2025): date, category, supplier, buyer, quantity, unit price, transaction type. This file holds aggregates from that database + the full list of 80 anomalous transactions.
A4: Anonymisation | B4: Supplier names, buyer names and order numbers are changed. PLN values are transformed, but proportions, shares, y/y changes and transaction counts are kept, so the conclusions are the same.
A5: File structure | B5: Dashboard – the view for a manager. Data_* – input data (aggregates and transactions). Calculations – helper metrics. Parameters – thresholds and benchmarks (you can change them). Every number on the dashboard is a formula.
A6: Price / quantity anomaly | B6: Transactions flagged in the source database (transaction type column): unit price or quantity clearly above normal.
A7: Price outlier | B7: A transaction with a unit price higher than the mean + 2 standard deviations (μ+2σ) in its category.
A8: Split order | B8: More than 1 transaction on the same day, by the same buyer, with the same supplier, in the same category – a possible split of one order to stay under the tender limit.
A9: Pareto | B9: How many suppliers (from the largest) are needed to cover 80% of spend. A high number = a spread-out supplier base and room to consolidate.
A10: Supplier rating | B10: Based on the number of anomalies: HIGH from 4, ELEVATED from 2, below that LOW (thresholds in the Parameters sheet).
A11: Buyer level | B11: Based on the number of anomalies: HIGH from 8, MEDIUM from 5, below that LOW.
A12: Outlier risk | B12: Based on the outlier value in a category: HIGH from 20 M PLN, MEDIUM from 5 M PLN.
A13: Inflation benchmark | B13: Polish PPI 2025 (GUS) ~3.5% y/y. Excess vs PPI = spend 2025 − spend 2024 × (1 + PPI).
... A16: Author | B16: Paweł Liberacki – pawelliberackicareer@gmail.com

Sheet Parameters
A1: Parameter | B1: Value | C1: Description
A2: Polish PPI 2025 (GUS, y/y) | B2: 0.035 | C2: Producer price inflation benchmark – reference point for year-on-year growth
A3: Supplier rating HIGH – min. anomalies | B3: 4 | C3: Number of anomalies from which a supplier is rated HIGH
A4: Supplier rating ELEVATED – min. anomalies | B4: 2 | C4: From this number the rating is ELEVATED (below: LOW)
A5: Buyer level HIGH – min. anomalies | B5: 8 | C5: Number of buyer anomalies for level HIGH
A6: Buyer level MEDIUM – min. anomalies | B6: 5 | C6: Number of buyer anomalies for level MEDIUM
A7: Outliers – risk HIGH from (M PLN) | B7: 20 | C7: Outlier value in a category for risk HIGH
A8: Outliers – risk MEDIUM from (M PLN) | B8: 5 | C8: Outlier value in a category for risk MEDIUM
A9: Pareto – share threshold | B9: 0.8 | C9: Share of spend used in the Pareto analysis
A10: KPI – max. share of one category | B10: 0.5 | C10: Target limit for spend concentration in one category
A11: Consolidation target – number of suppliers | B11: 30 | C11: Target number of suppliers after consolidation
A13: Cells with a yellow background and blue font can be changed – the whole dashboard recalculates automatically.

Sheet Data_Anomalies
A1: Order_ID | B1: Date | C1: Category | D1: Supplier | E1: Quantity | F1: Unit_price_PLN | G1: Buyer | H1: Anomaly_type | I1: Value_PLN
A2: PO-817370 | B2: 45535 | C2: IT Hardware | D2: SUP-46 | E2: 8500 | F2: 4495.69 | G2: BUYER-06 | H2: Quantity anomaly | I2: =E2*F2 -> 38213365
A3: PO-663941 | B3: 45509 | C3: IT Hardware | D3: SUP-14 | E3: 5500 | F3: 4025.1 | G3: BUYER-09 | H3: Quantity anomaly | I3: =E3*F3 -> 22138050
A4: PO-417578 | B4: 45738 | C4: IT Hardware | D4: SUP-30 | E4: 4600 | F4: 3767.33 | G4: BUYER-02 | H4: Quantity anomaly | I4: =E4*F4 -> 17329718
A5: PO-393878 | B5: 45993 | C5: IT Hardware | D5: SUP-12 | E5: 2700 | F5: 5104.7 | G5: BUYER-02 | H5: Quantity anomaly | I5: =E5*F5 -> 13782690
A6: PO-474907 | B6: 45874 | C6: Marketing Services | D6: SUP-12 | E6: 9400 | F6: 1114.15 | G6: BUYER-03 | H6: Quantity anomaly | I6: =E6*F6 -> 10473010
A7: PO-130587 | B7: 45784 | C7: Marketing Services | D7: SUP-33 | E7: 8700 | F7: 1151.06 | G7: BUYER-05 | H7: Quantity anomaly | I7: =E7*F7 -> 10014222
A8: PO-610335 | B8: 45738 | C8: Marketing Services | D8: SUP-22 | E8: 5900 | F8: 1358.05 | G8: BUYER-09 | H8: Quantity anomaly | I8: =E8*F8 -> 8012495
A9: PO-943739 | B9: 45863 | C9: Marketing Services | D9: SUP-43 | E9: 5900 | F9: 1126.04 | G9: BUYER-08 | H9: Quantity anomaly | I9: =E9*F9 -> 6643636
A10: PO-467498 | B10: 45843 | C10: Media & Energy | D10: SUP-27 | E10: 9800 | F10: 639.41 | G10: BUYER-08 | H10: Quantity anomaly | I10: =E10*F10 -> 6266218
A11: PO-330583 | B11: 45508 | C11: IT Hardware | D11: SUP-23 | E11: 74 | F11: 75303.33 | G11: BUYER-05 | H11: Price anomaly | I11: =E11*F11 -> 5572446.4
A12: PO-708043 | B12: 45653 | C12: Marketing Services | D12: SUP-01 | E12: 3100 | F12: 1538.91 | G12: BUYER-02 | H12: Quantity anomaly | I12: =E12*F12 -> 4770621
A13: PO-777420 | B13: 45674 | C13: Marketing Services | D13: SUP-35 | E13: 3300 | F13: 1348.4 | G13: BUYER-06 | H13: Quantity anomaly | I13: =E13*F13 -> 4449720
... A81: PO-726341 | B81: 45636 | C81: Raw Materials | D81: SUP-31 | E81: 1 | F81: 3030.98 | G81: BUYER-08 | H81: Price anomaly | I81: =E81*F81 -> 3030.98
A83: Transactions flagged as anomalies in the source database. Value_PLN = Quantity × Unit_price_PLN.

Sheet Data_Suppliers
A1: Supplier | B1: Spend_PLN | C1: Txn_count | D1: Avg_txn_value | E1: Spend_share | F1: Anomaly_count | G1: Anomaly_value_PLN | H1: Risk_rating | I1: Cumulative_share | J1: IT Hardware | K1: Marketing Services | L1: Media & Energy | M1: Logistics | N1: Raw Materials | O1: Office Supplies | P1: Top_anomaly_category
A2: SUP-18 | B2: 179753375 | C2: 2012 | D2: =B2/C2 -> 89340.644 | E2: =B2/SUM($B$2:$B$51) -> 0.028552269 | F2: =COUNTIF(Data_Anomalies!$D$2:$D$81,A2) -> 0 | G2: =SUMIF(Data_Anomalies!$D$2:$D$81,A2,Data_Anomalies!$I$2:$I$81) -> 0 | H2: =IF(F2>=Parameters!$B$3,"HIGH",IF(F2>=Parameters!$B$4,"ELEVATED","LOW")) -> LOW | I2: =SUMIF($B$2:$B$51,">="&B2)/SUM($B$2:$B$51) -> 0.028552269 | J2: =SUMIFS(Data_Anomalies!$I$2:$I$81,Data_Anomalies!$D$2:$D$81,$A2,Data_Anomalies!$C$2:$C$81,J$1) -> 0 | K2: =SUMIFS(Data_Anomalies!$I$2:$I$81,Data_Anomalies!$D$2:$D$81,$A2,Data_Anomalies!$C$2:$C$81,K$1) -> 0 | L2: =SUMIFS(Data_Anomalies!$I$2:$I$81,Data_Anomalies!$D$2:$D$81,$A2,Data_Anomalies!$C$2:$C$81,L$1) -> 0 | M2: =SUMIFS(Data_Anomalies!$I$2:$I$81,Data_Anomalies!$D$2:$D$81,$A2,Data_Anomalies!$C$2:$C$81,M$1) -> 0 | N2: =SUMIFS(Data_Anomalies!$I$2:$I$81,Data_Anomalies!$D$2:$D$81,$A2,Data_Anomalies!$C$2:$C$81,N$1) -> 0 | O2: =SUMIFS(Data_Anomalies!$I$2:$I$81,Data_Anomalies!$D$2:$D$81,$A2,Data_Anomalies!$C$2:$C$81,O$1) -> 0 | P2: =IF(G2=0,"—",INDEX($J$1:$O$1,MATCH(MAX(J2:O2),J2:O2,0))) -> —
A3: SUP-46 | B3: 159930853 | C3: 1988 | D3: =B3/C3 -> 80448.115 | E3: =B3/SUM($B$2:$B$51) -> 0.025403633 | F3: =COUNTIF(Data_Anomalies!$D$2:$D$81,A3) -> 2 | G3: =SUMIF(Data_Anomalies!$D$2:$D$81,A3,Data_Anomalies!$I$2:$I$81) -> 38217839 | H3: =IF(F3>=Parameters!$B$3,"HIGH",IF(F3>=Parameters!$B$4,"ELEVATED","LOW")) -> ELEVATED | I3: =SUMIF($B$2:$B$51,">="&B3)/SUM($B$2:$B$51) -> 0.053955903 | J3: =SUMIFS(Data_Anomalies!$I$2:$I$81,Data_Anomalies!$D$2:$D$81,$A3,Data_Anomalies!$C$2:$C$81,J$1) -> 38213365 | K3: =SUMIFS(Data_Anomalies!$I$2:$I$81,Data_Anomalies!$D$2:$D$81,$A3,Data_Anomalies!$C$2:$C$81,K$1) -> 0 | L3: =SUMIFS(Data_Anomalies!$I$2:$I$81,Data_Anomalies!$D$2:$D$81,$A3,Data_Anomalies!$C$2:$C$81,L$1) -> 0 | M3: =SUMIFS(Data_Anomalies!$I$2:$I$81,Data_Anomalies!$D$2:$D$81,$A3,Data_Anomalies!$C$2:$C$81,M$1) -> 0 | N3: =SUMIFS(Data_Anomalies!$I$2:$I$81,Data_Anomalies!$D$2:$D$81,$A3,Data_Anomalies!$C$2:$C$81,N$1) -> 0 | O3: =SUMIFS(Data_Anomalies!$I$2:$I$81,Data_Anomalies!$D$2:$D$81,$A3,Data_Anomalies!$C$2:$C$81,O$1) -> 4474.14 | P3: =IF(G3=0,"—",INDEX($J$1:$O$1,MATCH(MAX(J3:O3),J3:O3,0))) -> IT Hardware
A4: SUP-12 | B4: 148038153 | C4: 1976 | D4: =B4/C4 -> 74918.094 | E4: =B4/SUM($B$2:$B$51) -> 0.023514581 | F4: =COUNTIF(Data_Anomalies!$D$2:$D$81,A4) -> 6 | G4: =SUMIF(Data_Anomalies!$D$2:$D$81,A4,Data_Anomalies!$I$2:$I$81) -> 29146079 | H4: =IF(F4>=Parameters!$B$3,"HIGH",IF(F4>=Parameters!$B$4,"ELEVATED","LOW")) -> HIGH | I4: =SUMIF($B$2:$B$51,">="&B4)/SUM($B$2:$B$51) -> 0.077470483 | J4: =SUMIFS(Data_Anomalies!$I$2:$I$81,Data_Anomalies!$D$2:$D$81,$A4,Data_Anomalies!$C$2:$C$81,J$1) -> 18230716 | K4: =SUMIFS(Data_Anomalies!$I$2:$I$81,Data_Anomalies!$D$2:$D$81,$A4,Data_Anomalies!$C$2:$C$81,K$1) -> 10473010 | L4: =SUMIFS(Data_Anomalies!$I$2:$I$81,Data_Anomalies!$D$2:$D$81,$A4,Data_Anomalies!$C$2:$C$81,L$1) -> 0 | M4: =SUMIFS(Data_Anomalies!$I$2:$I$81,Data_Anomalies!$D$2:$D$81,$A4,Data_Anomalies!$C$2:$C$81,M$1) -> 27115.26 | N4: =SUMIFS(Data_Anomalies!$I$2:$I$81,Data_Anomalies!$D$2:$D$81,$A4,Data_Anomalies!$C$2:$C$81,N$1) -> 72661.96 | O4: =SUMIFS(Data_Anomalies!$I$2:$I$81,Data_Anomalies!$D$2:$D$81,$A4,Data_Anomalies!$C$2:$C$81,O$1) -> 342576 | P4: =IF(G4=0,"—",INDEX($J$1:$O$1,MATCH(MAX(J4:O4),J4:O4,0))) -> IT Hardware
A5: SUP-14 | B5: 147786075 | C5: 2073 | D5: =B5/C5 -> 71290.919 | E5: =B5/SUM($B$2:$B$51) -> 0.02347454 | F5: =COUNTIF(Data_Anomalies!$D$2:$D$81,A5) -> 3 | G5: =SUMIF(Data_Anomalies!$D$2:$D$81,A5,Data_Anomalies!$I$2:$I$81) -> 27107150 | H5: =IF(F5>=Parameters!$B$3,"HIGH",IF(F5>=Parameters!$B$4,"ELEVATED","LOW")) -> ELEVATED | I5: =SUMIF($B$2:$B$51,">="&B5)/SUM($B$2:$B$51) -> 0.10094502 | J5: =SUMIFS(Data_Anomalies!$I$2:$I$81,Data_Anomalies!$D$2:$D$81,$A5,Data_Anomalies!$C$2:$C$81,J$1) -> 22138050 | K5: =SUMIFS(Data_Anomalies!$I$2:$I$81,Data_Anomalies!$D$2:$D$81,$A5,Data_Anomalies!$C$2:$C$81,K$1) -> 0 | L5: =SUMIFS(Data_Anomalies!$I$2:$I$81,Data_Anomalies!$D$2:$D$81,$A5,Data_Anomalies!$C$2:$C$81,L$1) -> 3936900 | M5: =SUMIFS(Data_Anomalies!$I$2:$I$81,Data_Anomalies!$D$2:$D$81,$A5,Data_Anomalies!$C$2:$C$81,M$1) -> 0 | N5: =SUMIFS(Data_Anomalies!$I$2:$I$81,Data_Anomalies!$D$2:$D$81,$A5,Data_Anomalies!$C$2:$C$81,N$1) -> 1032200 | O5: =SUMIFS(Data_Anomalies!$I$2:$I$81,Data_Anomalies!$D$2:$D$81,$A5,Data_Anomalies!$C$2:$C$81,O$1) -> 0 | P5: =IF(G5=0,"—",INDEX($J$1:$O$1,MATCH(MAX(J5:O5),J5:O5,0))) -> IT Hardware
A6: SUP-30 | B6: 143315737 | C6: 2012 | D6: =B6/C6 -> 71230.486 | E6: =B6/SUM($B$2:$B$51) -> 0.022764466 | F6: =COUNTIF(Data_Anomalies!$D$2:$D$81,A6) -> 3 | G6: =SUMIF(Data_Anomalies!$D$2:$D$81,A6,Data_Anomalies!$I$2:$I$81) -> 19467356 | H6: =IF(F6>=Parameters!$B$3,"HIGH",IF(F6>=Parameters!$B$4,"ELEVATED","LOW")) -> ELEVATED | I6: =SUMIF($B$2:$B$51,">="&B6)/SUM($B$2:$B$51) -> 0.12370949 | J6: =SUMIFS(Data_Anomalies!$I$2:$I$81,Data_Anomalies!$D$2:$D$81,$A6,Data_Anomalies!$C$2:$C$81,J$1) -> 19353298 | K6: =SUMIFS(Data_Anomalies!$I$2:$I$81,Data_Anomalies!$D$2:$D$81,$A6,Data_Anomalies!$C$2:$C$81,K$1) -> 0 | L6: =SUMIFS(Data_Anomalies!$I$2:$I$81,Data_Anomalies!$D$2:$D$81,$A6,Data_Anomalies!$C$2:$C$81,L$1) -> 0 | M6: =SUMIFS(Data_Anomalies!$I$2:$I$81,Data_Anomalies!$D$2:$D$81,$A6,Data_Anomalies!$C$2:$C$81,M$1) -> 0 | N6: =SUMIFS(Data_Anomalies!$I$2:$I$81,Data_Anomalies!$D$2:$D$81,$A6,Data_Anomalies!$C$2:$C$81,N$1) -> 114057.6 | O6: =SUMIFS(Data_Anomalies!$I$2:$I$81,Data_Anomalies!$D$2:$D$81,$A6,Data_Anomalies!$C$2:$C$81,O$1) -> 0 | P6: =IF(G6=0,"—",INDEX($J$1:$O$1,MATCH(MAX(J6:O6),J6:O6,0))) -> IT Hardware
A7: SUP-27 | B7: 135626018 | C7: 2019 | D7: =B7/C7 -> 67174.848 | E7: =B7/SUM($B$2:$B$51) -> 0.02154302 | F7: =COUNTIF(Data_Anomalies!$D$2:$D$81,A7) -> 2 | G7: =SUMIF(Data_Anomalies!$D$2:$D$81,A7,Data_Anomalies!$I$2:$I$81) -> 6753752.4 | H7: =IF(F7>=Parameters!$B$3,"HIGH",IF(F7>=Parameters!$B$4,"ELEVATED","LOW")) -> ELEVATED | I7: =SUMIF($B$2:$B$51,">="&B7)/SUM($B$2:$B$51) -> 0.14525251 | J7: =SUMIFS(Data_Anomalies!$I$2:$I$81,Data_Anomalies!$D$2:$D$81,$A7,Data_Anomalies!$C$2:$C$81,J$1) -> 0 | K7: =SUMIFS(Data_Anomalies!$I$2:$I$81,Data_Anomalies!$D$2:$D$81,$A7,Data_Anomalies!$C$2:$C$81,K$1) -> 0 | L7: =SUMIFS(Data_Anomalies!$I$2:$I$81,Data_Anomalies!$D$2:$D$81,$A7,Data_Anomalies!$C$2:$C$81,L$1) -> 6266218 | M7: =SUMIFS(Data_Anomalies!$I$2:$I$81,Data_Anomalies!$D$2:$D$81,$A7,Data_Anomalies!$C$2:$C$81,M$1) -> 487534.41 | N7: =SUMIFS(Data_Anomalies!$I$2:$I$81,Data_Anomalies!$D$2:$D$81,$A7,Data_Anomalies!$C$2:$C$81,N$1) -> 0 | O7: =SUMIFS(Data_Anomalies!$I$2:$I$81,Data_Anomalies!$D$2:$D$81,$A7,Data_Anomalies!$C$2:$C$81,O$1) -> 0 | P7: =IF(G7=0,"—",INDEX($J$1:$O$1,MATCH(MAX(J7:O7),J7:O7,0))) -> Media & Energy
A8: SUP-47 | B8: 133400177 | C8: 2084 | D8: =B8/C8 -> 64011.601 | E8: =B8/SUM($B$2:$B$51) -> 0.021189465 | F8: =COUNTIF(Data_Anomalies!$D$2:$D$81,A8) -> 2 | G8: =SUMIF(Data_Anomalies!$D$2:$D$81,A8,Data_Anomalies!$I$2:$I$81) -> 3332472.9 | H8: =IF(F8>=Parameters!$B$3,"HIGH",IF(F8>=Parameters!$B$4,"ELEVATED","LOW")) -> ELEVATED | I8: =SUMIF($B$2:$B$51,">="&B8)/SUM($B$2:$B$51) -> 0.16644197 | J8: =SUMIFS(Data_Anomalies!$I$2:$I$81,Data_Anomalies!$D$2:$D$81,$A8,Data_Anomalies!$C$2:$C$81,J$1) -> 2793813.9 | K8: =SUMIFS(Data_Anomalies!$I$2:$I$81,Data_Anomalies!$D$2:$D$81,$A8,Data_Anomalies!$C$2:$C$81,K$1) -> 0 | L8: =SUMIFS(Data_Anomalies!$I$2:$I$81,Data_Anomalies!$D$2:$D$81,$A8,Data_Anomalies!$C$2:$C$81,L$1) -> 0 | M8: =SUMIFS(Data_Anomalies!$I$2:$I$81,Data_Anomalies!$D$2:$D$81,$A8,Data_Anomalies!$C$2:$C$81,M$1) -> 0 | N8: =SUMIFS(Data_Anomalies!$I$2:$I$81,Data_Anomalies!$D$2:$D$81,$A8,Data_Anomalies!$C$2:$C$81,N$1) -> 0 | O8: =SUMIFS(Data_Anomalies!$I$2:$I$81,Data_Anomalies!$D$2:$D$81,$A8,Data_Anomalies!$C$2:$C$81,O$1) -> 538659 | P8: =IF(G8=0,"—",INDEX($J$1:$O$1,MATCH(MAX(J8:O8),J8:O8,0))) -> IT Hardware
A9: SUP-44 | B9: 131412367 | C9: 2016 | D9: =B9/C9 -> 65184.706 | E9: =B9/SUM($B$2:$B$51) -> 0.020873718 | F9: =COUNTIF(Data_Anomalies!$D$2:$D$81,A9) -> 2 | G9: =SUMIF(Data_Anomalies!$D$2:$D$81,A9,Data_Anomalies!$I$2:$I$81) -> 2322271.5 | H9: =IF(F9>=Parameters!$B$3,"HIGH",IF(F9>=Parameters!$B$4,"ELEVATED","LOW")) -> ELEVATED | I9: =SUMIF($B$2:$B$51,">="&B9)/SUM($B$2:$B$51) -> 0.18731569 | J9: =SUMIFS(Data_Anomalies!$I$2:$I$81,Data_Anomalies!$D$2:$D$81,$A9,Data_Anomalies!$C$2:$C$81,J$1) -> 0 | K9: =SUMIFS(Data_Anomalies!$I$2:$I$81,Data_Anomalies!$D$2:$D$81,$A9,Data_Anomalies!$C$2:$C$81,K$1) -> 2120602.5 | L9: =SUMIFS(Data_Anomalies!$I$2:$I$81,Data_Anomalies!$D$2:$D$81,$A9,Data_Anomalies!$C$2:$C$81,L$1) -> 0 | M9: =SUMIFS(Data_Anomalies!$I$2:$I$81,Data_Anomalies!$D$2:$D$81,$A9,Data_Anomalies!$C$2:$C$81,M$1) -> 0 | N9: =SUMIFS(Data_Anomalies!$I$2:$I$81,Data_Anomalies!$D$2:$D$81,$A9,Data_Anomalies!$C$2:$C$81,N$1) -> 0 | O9: =SUMIFS(Data_Anomalies!$I$2:$I$81,Data_Anomalies!$D$2:$D$81,$A9,Data_Anomalies!$C$2:$C$81,O$1) -> 201669 | P9: =IF(G9=0,"—",INDEX($J$1:$O$1,MATCH(MAX(J9:O9),J9:O9,0))) -> Marketing Services
A10: SUP-05 | B10: 131264849 | C10: 2053 | D10: =B10/C10 -> 63938.066 | E10: =B10/SUM($B$2:$B$51) -> 0.020850286 | F10: =COUNTIF(Data_Anomalies!$D$2:$D$81,A10) -> 0 | G10: =SUMIF(Data_Anomalies!$D$2:$D$81,A10,Data_Anomalies!$I$2:$I$81) -> 0 | H10: =IF(F10>=Parameters!$B$3,"HIGH",IF(F10>=Parameters!$B$4,"ELEVATED","LOW")) -> LOW | I10: =SUMIF($B$2:$B$51,">="&B10)/SUM($B$2:$B$51) -> 0.20816598 | J10: =SUMIFS(Data_Anomalies!$I$2:$I$81,Data_Anomalies!$D$2:$D$81,$A10,Data_Anomalies!$C$2:$C$81,J$1) -> 0 | K10: =SUMIFS(Data_Anomalies!$I$2:$I$81,Data_Anomalies!$D$2:$D$81,$A10,Data_Anomalies!$C$2:$C$81,K$1) -> 0 | L10: =SUMIFS(Data_Anomalies!$I$2:$I$81,Data_Anomalies!$D$2:$D$81,$A10,Data_Anomalies!$C$2:$C$81,L$1) -> 0 | M10: =SUMIFS(Data_Anomalies!$I$2:$I$81,Data_Anomalies!$D$2:$D$81,$A10,Data_Anomalies!$C$2:$C$81,M$1) -> 0 | N10: =SUMIFS(Data_Anomalies!$I$2:$I$81,Data_Anomalies!$D$2:$D$81,$A10,Data_Anomalies!$C$2:$C$81,N$1) -> 0 | O10: =SUMIFS(Data_Anomalies!$I$2:$I$81,Data_Anomalies!$D$2:$D$81,$A10,Data_Anomalies!$C$2:$C$81,O$1) -> 0 | P10: =IF(G10=0,"—",INDEX($J$1:$O$1,MATCH(MAX(J10:O10),J10:O10,0))) -> —
A11: SUP-39 | B11: 130938159 | C11: 2014 | D11: =B11/C11 -> 65013.982 | E11: =B11/SUM($B$2:$B$51) -> 0.020798394 | F11: =COUNTIF(Data_Anomalies!$D$2:$D$81,A11) -> 2 | G11: =SUMIF(Data_Anomalies!$D$2:$D$81,A11,Data_Anomalies!$I$2:$I$81) -> 2185128.7 | H11: =IF(F11>=Parameters!$B$3,"HIGH",IF(F11>=Parameters!$B$4,"ELEVATED","LOW")) -> ELEVATED | I11: =SUMIF($B$2:$B$51,">="&B11)/SUM($B$2:$B$51) -> 0.22896437 | J11: =SUMIFS(Data_Anomalies!$I$2:$I$81,Data_Anomalies!$D$2:$D$81,$A11,Data_Anomalies!$C$2:$C$81,J$1) -> 0 | K11: =SUMIFS(Data_Anomalies!$I$2:$I$81,Data_Anomalies!$D$2:$D$81,$A11,Data_Anomalies!$C$2:$C$81,K$1) -> 0 | L11: =SUMIFS(Data_Anomalies!$I$2:$I$81,Data_Anomalies!$D$2:$D$81,$A11,Data_Anomalies!$C$2:$C$81,L$1) -> 0 | M11: =SUMIFS(Data_Anomalies!$I$2:$I$81,Data_Anomalies!$D$2:$D$81,$A11,Data_Anomalies!$C$2:$C$81,M$1) -> 2153228 | N11: =SUMIFS(Data_Anomalies!$I$2:$I$81,Data_Anomalies!$D$2:$D$81,$A11,Data_Anomalies!$C$2:$C$81,N$1) -> 0 | O11: =SUMIFS(Data_Anomalies!$I$2:$I$81,Data_Anomalies!$D$2:$D$81,$A11,Data_Anomalies!$C$2:$C$81,O$1) -> 31900.7 | P11: =IF(G11=0,"—",INDEX($J$1:$O$1,MATCH(MAX(J11:O11),J11:O11,0))) -> Logistics
A12: SUP-04 | B12: 129965840 | C12: 2078 | D12: =B12/C12 -> 62543.715 | E12: =B12/SUM($B$2:$B$51) -> 0.02064395 | F12: =COUNTIF(Data_Anomalies!$D$2:$D$81,A12) -> 0 | G12: =SUMIF(Data_Anomalies!$D$2:$D$81,A12,Data_Anomalies!$I$2:$I$81) -> 0 | H12: =IF(F12>=Parameters!$B$3,"HIGH",IF(F12>=Parameters!$B$4,"ELEVATED","LOW")) -> LOW | I12: =SUMIF($B$2:$B$51,">="&B12)/SUM($B$2:$B$51) -> 0.24960832 | J12: =SUMIFS(Data_Anomalies!$I$2:$I$81,Data_Anomalies!$D$2:$D$81,$A12,Data_Anomalies!$C$2:$C$81,J$1) -> 0 | K12: =SUMIFS(Data_Anomalies!$I$2:$I$81,Data_Anomalies!$D$2:$D$81,$A12,Data_Anomalies!$C$2:$C$81,K$1) -> 0 | L12: =SUMIFS(Data_Anomalies!$I$2:$I$81,Data_Anomalies!$D$2:$D$81,$A12,Data_Anomalies!$C$2:$C$81,L$1) -> 0 | M12: =SUMIFS(Data_Anomalies!$I$2:$I$81,Data_Anomalies!$D$2:$D$81,$A12,Data_Anomalies!$C$2:$C$81,M$1) -> 0 | N12: =SUMIFS(Data_Anomalies!$I$2:$I$81,Data_Anomalies!$D$2:$D$81,$A12,Data_Anomalies!$C$2:$C$81,N$1) -> 0 | O12: =SUMIFS(Data_Anomalies!$I$2:$I$81,Data_Anomalies!$D$2:$D$81,$A12,Data_Anomalies!$C$2:$C$81,O$1) -> 0 | P12: =IF(G12=0,"—",INDEX($J$1:$O$1,MATCH(MAX(J12:O12),J12:O12,0))) -> —
A13: SUP-01 | B13: 129040275 | C13: 2018 | D13: =B13/C13 -> 63944.636 | E13: =B13/SUM($B$2:$B$51) -> 0.020496932 | F13: =COUNTIF(Data_Anomalies!$D$2:$D$81,A13) -> 5 | G13: =SUMIF(Data_Anomalies!$D$2:$D$81,A13,Data_Anomalies!$I$2:$I$81) -> 8209156.8 | H13: =IF(F13>=Parameters!$B$3,"HIGH",IF(F13>=Parameters!$B$4,"ELEVATED","LOW")) -> HIGH | I13: =SUMIF($B$2:$B$51,">="&B13)/SUM($B$2:$B$51) -> 0.27010525 | J13: =SUMIFS(Data_Anomalies!$I$2:$I$81,Data_Anomalies!$D$2:$D$81,$A13,Data_Anomalies!$C$2:$C$81,J$1) -> 0 | K13: =SUMIFS(Data_Anomalies!$I$2:$I$81,Data_Anomalies!$D$2:$D$81,$A13,Data_Anomalies!$C$2:$C$81,K$1) -> 5989722.7 | L13: =SUMIFS(Data_Anomalies!$I$2:$I$81,Data_Anomalies!$D$2:$D$81,$A13,Data_Anomalies!$C$2:$C$81,L$1) -> 0 | M13: =SUMIFS(Data_Anomalies!$I$2:$I$81,Data_Anomalies!$D$2:$D$81,$A13,Data_Anomalies!$C$2:$C$81,M$1) -> 115588.1 | N13: =SUMIFS(Data_Anomalies!$I$2:$I$81,Data_Anomalies!$D$2:$D$81,$A13,Data_Anomalies!$C$2:$C$81,N$1) -> 2103846 | O13: =SUMIFS(Data_Anomalies!$I$2:$I$81,Data_Anomalies!$D$2:$D$81,$A13,Data_Anomalies!$C$2:$C$81,O$1) -> 0 | P13: =IF(G13=0,"—",INDEX($J$1:$O$1,MATCH(MAX(J13:O13),J13:O13,0))) -> Marketing Services
... A51: SUP-45 | B51: 113895463 | C51: 1979 | D51: =B51/C51 -> 57552.028 | E51: =B51/SUM($B$2:$B$51) -> 0.018091309 | F51: =COUNTIF(Data_Anomalies!$D$2:$D$81,A51) -> 2 | G51: =SUMIF(Data_Anomalies!$D$2:$D$81,A51,Data_Anomalies!$I$2:$I$81) -> 227516.75 | H51: =IF(F51>=Parameters!$B$3,"HIGH",IF(F51>=Parameters!$B$4,"ELEVATED","LOW")) -> ELEVATED | I51: =SUMIF($B$2:$B$51,">="&B51)/SUM($B$2:$B$51) -> 1 | J51: =SUMIFS(Data_Anomalies!$I$2:$I$81,Data_Anomalies!$D$2:$D$81,$A51,Data_Anomalies!$C$2:$C$81,J$1) -> 0 | K51: =SUMIFS(Data_Anomalies!$I$2:$I$81,Data_Anomalies!$D$2:$D$81,$A51,Data_Anomalies!$C$2:$C$81,K$1) -> 0 | L51: =SUMIFS(Data_Anomalies!$I$2:$I$81,Data_Anomalies!$D$2:$D$81,$A51,Data_Anomalies!$C$2:$C$81,L$1) -> 0 | M51: =SUMIFS(Data_Anomalies!$I$2:$I$81,Data_Anomalies!$D$2:$D$81,$A51,Data_Anomalies!$C$2:$C$81,M$1) -> 0 | N51: =SUMIFS(Data_Anomalies!$I$2:$I$81,Data_Anomalies!$D$2:$D$81,$A51,Data_Anomalies!$C$2:$C$81,N$1) -> 0 | O51: =SUMIFS(Data_Anomalies!$I$2:$I$81,Data_Anomalies!$D$2:$D$81,$A51,Data_Anomalies!$C$2:$C$81,O$1) -> 227516.75 | P51: =IF(G51=0,"—",INDEX($J$1:$O$1,MATCH(MAX(J51:O51),J51:O51,0))) -> Office Supplies
A53: Spend and transaction count: aggregates from the 100,000-transaction database. Anomaly columns are formulas based on Data_Anomalies. Columns J–O: anomaly value of the supplier in each category.

Sheet Data_Buyers
A1: Buyer | B1: Spend_M_PLN | C1: Txn_count | D1: Avg_txn_value_PLN | E1: Anomaly_count | F1: Anomaly_value_PLN | G1: Share_of_anomaly_value | H1: Level
A2: BUYER-09 | B2: 655 | C2: 9887 | D2: =B2*1000000/C2 -> 66248.609 | E2: =COUNTIF(Data_Anomalies!$G$2:$G$81,A2) -> 10 | F2: =SUMIF(Data_Anomalies!$G$2:$G$81,A2,Data_Anomalies!$I$2:$I$81) -> 37437345 | G2: =F2/SUM(Data_Anomalies!$I$2:$I$81) -> 0.19457452 | H2: =IF(E2>=Parameters!$B$5,"HIGH",IF(E2>=Parameters!$B$6,"MEDIUM","LOW")) -> HIGH
A3: BUYER-06 | B3: 653.7 | C3: 10025 | D3: =B3*1000000/C3 -> 65206.983 | E3: =COUNTIF(Data_Anomalies!$G$2:$G$81,A3) -> 8 | F3: =SUMIF(Data_Anomalies!$G$2:$G$81,A3,Data_Anomalies!$I$2:$I$81) -> 47409539 | G3: =F3/SUM(Data_Anomalies!$I$2:$I$81) -> 0.24640338 | H3: =IF(E3>=Parameters!$B$5,"HIGH",IF(E3>=Parameters!$B$6,"MEDIUM","LOW")) -> HIGH
A4: BUYER-02 | B4: 645.6 | C4: 10015 | D4: =B4*1000000/C4 -> 64463.305 | E4: =COUNTIF(Data_Anomalies!$G$2:$G$81,A4) -> 8 | F4: =SUMIF(Data_Anomalies!$G$2:$G$81,A4,Data_Anomalies!$I$2:$I$81) -> 38967941 | G4: =F4/SUM(Data_Anomalies!$I$2:$I$81) -> 0.20252955 | H4: =IF(E4>=Parameters!$B$5,"HIGH",IF(E4>=Parameters!$B$6,"MEDIUM","LOW")) -> HIGH
A5: BUYER-10 | B5: 636.6 | C5: 10062 | D5: =B5*1000000/C5 -> 63267.74 | E5: =COUNTIF(Data_Anomalies!$G$2:$G$81,A5) -> 8 | F5: =SUMIF(Data_Anomalies!$G$2:$G$81,A5,Data_Anomalies!$I$2:$I$81) -> 8429281.3 | G5: =F5/SUM(Data_Anomalies!$I$2:$I$81) -> 0.04380982 | H5: =IF(E5>=Parameters!$B$5,"HIGH",IF(E5>=Parameters!$B$6,"MEDIUM","LOW")) -> HIGH
A6: BUYER-07 | B6: 631.2 | C6: 10143 | D6: =B6*1000000/C6 -> 62230.109 | E6: =COUNTIF(Data_Anomalies!$G$2:$G$81,A6) -> 8 | F6: =SUMIF(Data_Anomalies!$G$2:$G$81,A6,Data_Anomalies!$I$2:$I$81) -> 5174464.5 | G6: =F6/SUM(Data_Anomalies!$I$2:$I$81) -> 0.026893439 | H6: =IF(E6>=Parameters!$B$5,"HIGH",IF(E6>=Parameters!$B$6,"MEDIUM","LOW")) -> HIGH
A7: BUYER-03 | B7: 630.6 | C7: 10164 | D7: =B7*1000000/C7 -> 62042.503 | E7: =COUNTIF(Data_Anomalies!$G$2:$G$81,A7) -> 8 | F7: =SUMIF(Data_Anomalies!$G$2:$G$81,A7,Data_Anomalies!$I$2:$I$81) -> 13584969 | G7: =F7/SUM(Data_Anomalies!$I$2:$I$81) -> 0.070605668 | H7: =IF(E7>=Parameters!$B$5,"HIGH",IF(E7>=Parameters!$B$6,"MEDIUM","LOW")) -> HIGH
A8: BUYER-08 | B8: 616.2 | C8: 9946 | D8: =B8*1000000/C8 -> 61954.555 | E8: =COUNTIF(Data_Anomalies!$G$2:$G$81,A8) -> 10 | F8: =SUMIF(Data_Anomalies!$G$2:$G$81,A8,Data_Anomalies!$I$2:$I$81) -> 16359617 | G8: =F8/SUM(Data_Anomalies!$I$2:$I$81) -> 0.08502645 | H8: =IF(E8>=Parameters!$B$5,"HIGH",IF(E8>=Parameters!$B$6,"MEDIUM","LOW")) -> HIGH
A9: BUYER-04 | B9: 615.6 | C9: 9817 | D9: =B9*1000000/C9 -> 62707.548 | E9: =COUNTIF(Data_Anomalies!$G$2:$G$81,A9) -> 9 | F9: =SUMIF(Data_Anomalies!$G$2:$G$81,A9,Data_Anomalies!$I$2:$I$81) -> 5630451.8 | G9: =F9/SUM(Data_Anomalies!$I$2:$I$81) -> 0.029263358 | H9: =IF(E9>=Parameters!$B$5,"HIGH",IF(E9>=Parameters!$B$6,"MEDIUM","LOW")) -> HIGH
A10: BUYER-05 | B10: 614 | C10: 10062 | D10: =B10*1000000/C10 -> 61021.666 | E10: =COUNTIF(Data_Anomalies!$G$2:$G$81,A10) -> 7 | F10: =SUMIF(Data_Anomalies!$G$2:$G$81,A10,Data_Anomalies!$I$2:$I$81) -> 18629954 | G10: =F10/SUM(Data_Anomalies!$I$2:$I$81) -> 0.096826161 | H10: =IF(E10>=Parameters!$B$5,"HIGH",IF(E10>=Parameters!$B$6,"MEDIUM","LOW")) -> MEDIUM
A11: BUYER-01 | B11: 597 | C11: 9879 | D11: =B11*1000000/C11 -> 60431.218 | E11: =COUNTIF(Data_Anomalies!$G$2:$G$81,A11) -> 4 | F11: =SUMIF(Data_Anomalies!$G$2:$G$81,A11,Data_Anomalies!$I$2:$I$81) -> 782643.1 | G11: =F11/SUM(Data_Anomalies!$I$2:$I$81) -> 0.0040676604 | H11: =IF(E11>=Parameters!$B$5,"HIGH",IF(E11>=Parameters!$B$6,"MEDIUM","LOW")) -> LOW
A13: Spend and transaction count: aggregates from the source database. Anomalies are formulas based on Data_Anomalies.

Sheet Data_Categories
A1: Category | B1: Spend_2024_M_PLN | C1: Spend_2025_M_PLN | D1: Spend_total_M_PLN | E1: Share | F1: Change_yy | G1: Change_M_PLN | H1: Excess_vs_PPI_M_PLN
A2: IT Hardware | B2: 2025.35 | C2: 1974.23 | D2: =B2+C2 -> 3999.58 | E2: =D2/SUM($D$2:$D$7) -> 0.63530776 | F2: =C2/B2-1 -> -0.025240082 | G2: =C2-B2 -> -51.12 | H2: =C2-B2*(1+Parameters!$B$2) -> -122.00725
A3: Marketing Services | B3: 589.07 | C3: 629.79 | D3: =B3+C3 -> 1218.86 | E3: =D3/SUM($D$2:$D$7) -> 0.19360813 | F3: =C3/B3-1 -> 0.06912591 | G3: =C3-B3 -> 40.72 | H3: =C3-B3*(1+Parameters!$B$2) -> 20.10255
A4: Media & Energy | B4: 315.03 | C4: 316.86 | D4: =B4+C4 -> 631.89 | E4: =D4/SUM($D$2:$D$7) -> 0.10037169 | F4: =C4/B4-1 -> 0.0058089706 | G4: =C4-B4 -> 1.83 | H4: =C4-B4*(1+Parameters!$B$2) -> -9.19605
A5: Logistics | B5: 118.05 | C5: 122.34 | D5: =B5+C5 -> 240.39 | E5: =D5/SUM($D$2:$D$7) -> 0.038184417 | F5: =C5/B5-1 -> 0.036340534 | G5: =C5-B5 -> 4.29 | H5: =C5-B5*(1+Parameters!$B$2) -> 0.15825
A6: Raw Materials | B6: 82.54 | C6: 82.35 | D6: =B6+C6 -> 164.89 | E6: =D6/SUM($D$2:$D$7) -> 0.026191724 | F6: =C6/B6-1 -> -0.0023019142 | G6: =C6-B6 -> -0.19 | H6: =C6-B6*(1+Parameters!$B$2) -> -3.0789
A7: Office Supplies | B7: 19.99 | C7: 19.9 | D7: =B7+C7 -> 39.89 | E7: =D7/SUM($D$2:$D$7) -> 0.0063362719 | F7: =C7/B7-1 -> -0.0045022511 | G7: =C7-B7 -> -0.09 | H7: =C7-B7*(1+Parameters!$B$2) -> -0.78965
A9: Excess vs PPI = spend 2025 − spend 2024 × (1 + PPI). A positive value = growth faster than inflation.

Sheet Data_Months
A1: Month | B1: Spend_2024_M_PLN | C1: Spend_2025_M_PLN | D1: Change_M_PLN | E1: Change_pct
A2: Jan | B2: 256.8 | C2: 261.1 | D2: =C2-B2 -> 4.3 | E2: =C2/B2-1 -> 0.016744548
A3: Feb | B3: 239.6 | C3: 236.1 | D3: =C3-B3 -> -3.5 | E3: =C3/B3-1 -> -0.014607679
A4: Mar | B4: 262.4 | C4: 282 | D4: =C4-B4 -> 19.6 | E4: =C4/B4-1 -> 0.074695122
A5: Apr | B5: 244.1 | C5: 255.5 | D5: =C5-B5 -> 11.4 | E5: =C5/B5-1 -> 0.046702171
A6: May | B6: 260 | C6: 271.3 | D6: =C6-B6 -> 11.3 | E6: =C6/B6-1 -> 0.043461538
A7: Jun | B7: 255.6 | C7: 254.9 | D7: =C7-B7 -> -0.7 | E7: =C7/B7-1 -> -0.0027386541
A8: Jul | B8: 260.4 | C8: 262.8 | D8: =C8-B8 -> 2.4 | E8: =C8/B8-1 -> 0.0092165899
A9: Aug | B9: 290.8 | C9: 272.5 | D9: =C9-B9 -> -18.3 | E9: =C9/B9-1 -> -0.062929849
A10: Sep | B10: 302.9 | C10: 261.1 | D10: =C10-B10 -> -41.8 | E10: =C10/B10-1 -> -0.13799934
A11: Oct | B11: 264.2 | C11: 270.2 | D11: =C11-B11 -> 6 | E11: =C11/B11-1 -> 0.022710068
A12: Nov | B12: 255.9 | C12: 261.9 | D12: =C12-B12 -> 6 | E12: =C12/B12-1 -> 0.023446659
A13: Dec | B13: 257.2 | C13: 255.9 | D13: =C13-B13 -> -1.3 | E13: =C13/B13-1 -> -0.0050544323

Sheet Data_Outliers
A1: Category | B1: Outlier_count | C1: Value_M_PLN | D1: Threshold_μ+2σ_PLN_per_unit | E1: Risk
A2: IT Hardware | B2: 76 | C2: 40.47 | D2: 7213 | E2: =IF(C2>=Parameters!$B$7,"HIGH",IF(C2>=Parameters!$B$8,"MEDIUM","LOW")) -> HIGH
A3: Media & Energy | B3: 166 | C3: 9.5 | D3: 1031 | E3: =IF(C3>=Parameters!$B$7,"HIGH",IF(C3>=Parameters!$B$8,"MEDIUM","LOW")) -> MEDIUM
A4: Marketing Services | B4: 27 | C4: 9.68 | D4: 2262 | E4: =IF(C4>=Parameters!$B$7,"HIGH",IF(C4>=Parameters!$B$8,"MEDIUM","LOW")) -> MEDIUM
A5: Logistics | B5: 13 | C5: 3.02 | D5: 510 | E5: =IF(C5>=Parameters!$B$7,"HIGH",IF(C5>=Parameters!$B$8,"MEDIUM","LOW")) -> LOW
A6: Raw Materials | B6: 10 | C6: 0.83 | D6: 320 | E6: =IF(C6>=Parameters!$B$7,"HIGH",IF(C6>=Parameters!$B$8,"MEDIUM","LOW")) -> LOW
A7: Office Supplies | B7: 12 | C7: 0.39 | D7: 82 | E7: =IF(C7>=Parameters!$B$7,"HIGH",IF(C7>=Parameters!$B$8,"MEDIUM","LOW")) -> LOW
A9: Outlier = a transaction with a unit price above the mean + 2 standard deviations in its category.
A11: Other figures from the source database
A12: Transactions in the database | B12: 100000
A13: Split orders – number of cases | B13: 2177
A14: Split orders – value M PLN | B14: 284.9
A15: Split order = more than 1 transaction on the same day, by the same buyer, with the same supplier, in the same category.

Sheet Calculations
A1: Metric | B1: Value | D1: Category | E1: Txn – price | F1: Txn – quantity | G1: M PLN – price | H1: M PLN – quantity
